Workbook
Name Instrument: INDEX(#REF!,#REF!):INDEX(#REF!,#REF!)
Name Instrument: INDEX(#REF!,#REF!):INDEX(#REF!,#REF!)
Name Instrument2: INDEX(#REF!,#REF!):INDEX(#REF!,#REF!)
Name Instrument2: INDEX(#REF!,#REF!):INDEX(#REF!,#REF!)
Name Sektioner: INDEX(#REF!,#REF!):INDEX(#REF!,#REF!)
Name Sektioner: INDEX(#REF!,#REF!):INDEX(#REF!,#REF!)
Name takstblad: [1]Takstblad!$A$2:$R$249
Name takstblad: [1]Takstblad!$A$2:$R$249
Name takstblad: Takstblad!$A$2:$T$276
Name TAP: Takstblad!$A$34:$A$54
Name Text2: 'Cover letter'!#REF!
Name Text2: 'Cover letter ECE_MPE'!#REF!
Name Text3: 'Cover letter'!$A$14
Name Text3: 'Cover letter ECE_MPE'!$A$14
Name VIP: Takstblad!$A$5:$A$30

Sheet Takstblad
A1: Rate Catalog - incl. Salary and price increase | C1: Hvis der tastes en medarbejder inkl. Kostpris ind, så skriv PhD I kolonne B, idet den så medtages I forskningsadministrationsberegningen
C2: Monthly Salary | N2: Cost Price
A3: Kategori | C3: 2026 | D3: =+C3+1 -> 2027 | E3: =+D3+1 -> 2028 | F3: =+E3+1 -> 2029 | G3: =+F3+1 -> 2030 | H3: =+G3+1 -> 2031 | I3: =+H3+1 -> 2032 | J3: =+I3+1 -> 2033 | K3: =+J3+1 -> 2034 | L3: =+K3+1 -> 2035 | N3: =+C3 -> 2026 | O3: =+D3 -> 2027 | P3: =+E3 -> 2028 | Q3: =+F3 -> 2029 | R3: =+G3 -> 2030 | S3: =+H3 -> 2031 | T3: =+I3 -> 2032 | U3: =+J3 -> 2033 | ... W3: =+L3 -> 2035 | Y3: Løn stigning | Z3: 1.025
A4: VIP | C4: Column1 | Y4: Prisstigning | Z4: 1.02
A5: "Choose job position" | B5: =_xlfn.XLOOKUP(Tabel12[[#This Row],[VIP]],Tabel19[Job functions],Tabel19[Column1],"",0)&"" | Y5: Timer/md | Z5: =1460/12 -> 121.66667
A6: Institutleader/Head of Research | B6: =_xlfn.XLOOKUP(Tabel12[[#This Row],[VIP]],Tabel19[Job functions],Tabel19[Column1],"",0)&"" | C6: 114000 | D6: =ROUNDUP(+C6*$Z$3,-3) -> 117000 | E6: =ROUNDUP(+D6*$Z$3,-3) -> 120000 | F6: =ROUNDUP(+E6*$Z$3,-3) -> 123000 | G6: =ROUNDUP(+F6*$Z$3,-3) -> 127000 | H6: =ROUNDUP(+G6*$Z$3,-3) -> 131000 | I6: =ROUNDUP(+H6*$Z$3,-3) -> 135000 | J6: =ROUNDUP(+I6*$Z$3,-3) -> 139000 | K6: =ROUNDUP(+J6*$Z$3,-3) -> 143000 | L6: =ROUNDUP(+K6*$Z$3,-3) -> 147000 | N6: =+C6/$Z$5 -> 936.9863 | O6: =+D6/$Z$5 -> 961.64384 | P6: =+E6/$Z$5 -> 986.30137 | Q6: =+F6/$Z$5 -> 1010.9589 | R6: =+G6/$Z$5 -> 1043.8356 | S6: =+H6/$Z$5 -> 1076.7123 | T6: =+I6/$Z$5 -> 1109.589 | U6: =+J6/$Z$5 -> 1142.4658 | ... W6: =+L6/$Z$5 -> 1208.2192
A7: Professor - high rate | B7: =_xlfn.XLOOKUP(Tabel12[[#This Row],[VIP]],Tabel19[Job functions],Tabel19[Column1],"",0)&"" | C7: 90000 | D7: =ROUNDUP(+C7*$Z$3,-3) -> 93000 | E7: =ROUNDUP(+D7*$Z$3,-3) -> 96000 | F7: =ROUNDUP(+E7*$Z$3,-3) -> 99000 | G7: =ROUNDUP(+F7*$Z$3,-3) -> 102000 | H7: =ROUNDUP(+G7*$Z$3,-3) -> 105000 | I7: =ROUNDUP(+H7*$Z$3,-3) -> 108000 | J7: =ROUNDUP(+I7*$Z$3,-3) -> 111000 | K7: =ROUNDUP(+J7*$Z$3,-3) -> 114000 | L7: =ROUNDUP(+K7*$Z$3,-3) -> 117000 | N7: =+C7/$Z$5 -> 739.72603 | O7: =+D7/$Z$5 -> 764.38356 | P7: =+E7/$Z$5 -> 789.0411 | Q7: =+F7/$Z$5 -> 813.69863 | R7: =+G7/$Z$5 -> 838.35616 | S7: =+H7/$Z$5 -> 863.0137 | T7: =+I7/$Z$5 -> 887.67123 | U7: =+J7/$Z$5 -> 912.32877 | ... W7: =+L7/$Z$5 -> 961.64384
A8: Professor - avr. rate | B8: =_xlfn.XLOOKUP(Tabel12[[#This Row],[VIP]],Tabel19[Job functions],Tabel19[Column1],"",0)&"" | C8: 87000 | D8: =ROUNDUP(+C8*$Z$3,-3) -> 90000 | E8: =ROUNDUP(+D8*$Z$3,-3) -> 93000 | F8: =ROUNDUP(+E8*$Z$3,-3) -> 96000 | G8: =ROUNDUP(+F8*$Z$3,-3) -> 99000 | H8: =ROUNDUP(+G8*$Z$3,-3) -> 102000 | I8: =ROUNDUP(+H8*$Z$3,-3) -> 105000 | J8: =ROUNDUP(+I8*$Z$3,-3) -> 108000 | K8: =ROUNDUP(+J8*$Z$3,-3) -> 111000 | L8: =ROUNDUP(+K8*$Z$3,-3) -> 114000 | N8: =+C8/$Z$5 -> 715.06849 | O8: =+D8/$Z$5 -> 739.72603 | P8: =+E8/$Z$5 -> 764.38356 | Q8: =+F8/$Z$5 -> 789.0411 | R8: =+G8/$Z$5 -> 813.69863 | S8: =+H8/$Z$5 -> 838.35616 | T8: =+I8/$Z$5 -> 863.0137 | U8: =+J8/$Z$5 -> 887.67123 | ... W8: =+L8/$Z$5 -> 936.9863
A9: Research Director - high rate | B9: =_xlfn.XLOOKUP(Tabel12[[#This Row],[VIP]],Tabel19[Job functions],Tabel19[Column1],"",0)&"" | C9: 90000 | D9: =ROUNDUP(+C9*$Z$3,-3) -> 93000 | E9: =ROUNDUP(+D9*$Z$3,-3) -> 96000 | F9: =ROUNDUP(+E9*$Z$3,-3) -> 99000 | G9: =ROUNDUP(+F9*$Z$3,-3) -> 102000 | H9: =ROUNDUP(+G9*$Z$3,-3) -> 105000 | I9: =ROUNDUP(+H9*$Z$3,-3) -> 108000 | J9: =ROUNDUP(+I9*$Z$3,-3) -> 111000 | K9: =ROUNDUP(+J9*$Z$3,-3) -> 114000 | L9: =ROUNDUP(+K9*$Z$3,-3) -> 117000 | N9: =+C9/$Z$5 -> 739.72603 | O9: =+D9/$Z$5 -> 764.38356 | P9: =+E9/$Z$5 -> 789.0411 | Q9: =+F9/$Z$5 -> 813.69863 | R9: =+G9/$Z$5 -> 838.35616 | S9: =+H9/$Z$5 -> 863.0137 | T9: =+I9/$Z$5 -> 887.67123 | U9: =+J9/$Z$5 -> 912.32877 | ... W9: =+L9/$Z$5 -> 961.64384
A10: Research Director - avr. rate | B10: =_xlfn.XLOOKUP(Tabel12[[#This Row],[VIP]],Tabel19[Job functions],Tabel19[Column1],"",0)&"" | C10: 87000 | D10: =ROUNDUP(+C10*$Z$3,-3) -> 90000 | E10: =ROUNDUP(+D10*$Z$3,-3) -> 93000 | F10: =ROUNDUP(+E10*$Z$3,-3) -> 96000 | G10: =ROUNDUP(+F10*$Z$3,-3) -> 99000 | H10: =ROUNDUP(+G10*$Z$3,-3) -> 102000 | I10: =ROUNDUP(+H10*$Z$3,-3) -> 105000 | J10: =ROUNDUP(+I10*$Z$3,-3) -> 108000 | K10: =ROUNDUP(+J10*$Z$3,-3) -> 111000 | L10: =ROUNDUP(+K10*$Z$3,-3) -> 114000 | N10: =+C10/$Z$5 -> 715.06849 | O10: =+D10/$Z$5 -> 739.72603 | P10: =+E10/$Z$5 -> 764.38356 | Q10: =+F10/$Z$5 -> 789.0411 | R10: =+G10/$Z$5 -> 813.69863 | S10: =+H10/$Z$5 -> 838.35616 | T10: =+I10/$Z$5 -> 863.0137 | U10: =+J10/$Z$5 -> 887.67123 | ... W10: =+L10/$Z$5 -> 936.9863
A11: Associate Professor - high rate | B11: =_xlfn.XLOOKUP(Tabel12[[#This Row],[VIP]],Tabel19[Job functions],Tabel19[Column1],"",0)&"" | C11: 73000 | D11: =ROUNDUP(+C11*$Z$3,-3) -> 75000 | E11: =ROUNDUP(+D11*$Z$3,-3) -> 77000 | F11: =ROUNDUP(+E11*$Z$3,-3) -> 79000 | G11: =ROUNDUP(+F11*$Z$3,-3) -> 81000 | H11: =ROUNDUP(+G11*$Z$3,-3) -> 84000 | I11: =ROUNDUP(+H11*$Z$3,-3) -> 87000 | J11: =ROUNDUP(+I11*$Z$3,-3) -> 90000 | K11: =ROUNDUP(+J11*$Z$3,-3) -> 93000 | L11: =ROUNDUP(+K11*$Z$3,-3) -> 96000 | N11: =+C11/$Z$5 -> 600 | O11: =+D11/$Z$5 -> 616.43836 | P11: =+E11/$Z$5 -> 632.87671 | Q11: =+F11/$Z$5 -> 649.31507 | R11: =+G11/$Z$5 -> 665.75342 | S11: =+H11/$Z$5 -> 690.41096 | T11: =+I11/$Z$5 -> 715.06849 | U11: =+J11/$Z$5 -> 739.72603 | ... W11: =+L11/$Z$5 -> 789.0411
A12: Associate Professor - avr. rate | B12: =_xlfn.XLOOKUP(Tabel12[[#This Row],[VIP]],Tabel19[Job functions],Tabel19[Column1],"",0)&"" | C12: 70000 | D12: =ROUNDUP(+C12*$Z$3,-3) -> 72000 | E12: =ROUNDUP(+D12*$Z$3,-3) -> 74000 | F12: =ROUNDUP(+E12*$Z$3,-3) -> 76000 | G12: =ROUNDUP(+F12*$Z$3,-3) -> 78000 | H12: =ROUNDUP(+G12*$Z$3,-3) -> 80000 | I12: =ROUNDUP(+H12*$Z$3,-3) -> 82000 | J12: =ROUNDUP(+I12*$Z$3,-3) -> 85000 | K12: =ROUNDUP(+J12*$Z$3,-3) -> 88000 | L12: =ROUNDUP(+K12*$Z$3,-3) -> 91000 | N12: =+C12/$Z$5 -> 575.34247 | O12: =+D12/$Z$5 -> 591.78082 | P12: =+E12/$Z$5 -> 608.21918 | Q12: =+F12/$Z$5 -> 624.65753 | R12: =+G12/$Z$5 -> 641.09589 | S12: =+H12/$Z$5 -> 657.53425 | T12: =+I12/$Z$5 -> 673.9726 | U12: =+J12/$Z$5 -> 698.63014 | ... W12: =+L12/$Z$5 -> 747.94521
A13: Senior Researcher - high rate | B13: =_xlfn.XLOOKUP(Tabel12[[#This Row],[VIP]],Tabel19[Job functions],Tabel19[Column1],"",0)&"" | C13: 74000 | D13: =ROUNDUP(+C13*$Z$3,-3) -> 76000 | E13: =ROUNDUP(+D13*$Z$3,-3) -> 78000 | F13: =ROUNDUP(+E13*$Z$3,-3) -> 80000 | G13: =ROUNDUP(+F13*$Z$3,-3) -> 82000 | H13: =ROUNDUP(+G13*$Z$3,-3) -> 85000 | I13: =ROUNDUP(+H13*$Z$3,-3) -> 88000 | J13: =ROUNDUP(+I13*$Z$3,-3) -> 91000 | K13: =ROUNDUP(+J13*$Z$3,-3) -> 94000 | L13: =ROUNDUP(+K13*$Z$3,-3) -> 97000 | N13: =+C13/$Z$5 -> 608.21918 | O13: =+D13/$Z$5 -> 624.65753 | P13: =+E13/$Z$5 -> 641.09589 | Q13: =+F13/$Z$5 -> 657.53425 | R13: =+G13/$Z$5 -> 673.9726 | S13: =+H13/$Z$5 -> 698.63014 | T13: =+I13/$Z$5 -> 723.28767 | U13: =+J13/$Z$5 -> 747.94521 | ... W13: =+L13/$Z$5 -> 797.26027
A14: Senior Researcher - avr. rate | B14: =_xlfn.XLOOKUP(Tabel12[[#This Row],[VIP]],Tabel19[Job functions],Tabel19[Column1],"",0)&"" | C14: 71000 | D14: =ROUNDUP(+C14*$Z$3,-3) -> 73000 | E14: =ROUNDUP(+D14*$Z$3,-3) -> 75000 | F14: =ROUNDUP(+E14*$Z$3,-3) -> 77000 | G14: =ROUNDUP(+F14*$Z$3,-3) -> 79000 | H14: =ROUNDUP(+G14*$Z$3,-3) -> 81000 | I14: =ROUNDUP(+H14*$Z$3,-3) -> 84000 | J14: =ROUNDUP(+I14*$Z$3,-3) -> 87000 | K14: =ROUNDUP(+J14*$Z$3,-3) -> 90000 | L14: =ROUNDUP(+K14*$Z$3,-3) -> 93000 | N14: =+C14/$Z$5 -> 583.56164 | O14: =+D14/$Z$5 -> 600 | P14: =+E14/$Z$5 -> 616.43836 | Q14: =+F14/$Z$5 -> 632.87671 | R14: =+G14/$Z$5 -> 649.31507 | S14: =+H14/$Z$5 -> 665.75342 | T14: =+I14/$Z$5 -> 690.41096 | U14: =+J14/$Z$5 -> 715.06849 | ... W14: =+L14/$Z$5 -> 764.38356
A15: Assistant Professor | B15: =_xlfn.XLOOKUP(Tabel12[[#This Row],[VIP]],Tabel19[Job functions],Tabel19[Column1],"",0)&"" | C15: 55000 | D15: =ROUNDUP(+C15*$Z$3,-3) -> 57000 | E15: =ROUNDUP(+D15*$Z$3,-3) -> 59000 | F15: =ROUNDUP(+E15*$Z$3,-3) -> 61000 | G15: =ROUNDUP(+F15*$Z$3,-3) -> 63000 | H15: =ROUNDUP(+G15*$Z$3,-3) -> 65000 | I15: =ROUNDUP(+H15*$Z$3,-3) -> 67000 | J15: =ROUNDUP(+I15*$Z$3,-3) -> 69000 | K15: =ROUNDUP(+J15*$Z$3,-3) -> 71000 | L15: =ROUNDUP(+K15*$Z$3,-3) -> 73000 | N15: =+C15/$Z$5 -> 452.05479 | O15: =+D15/$Z$5 -> 468.49315 | P15: =+E15/$Z$5 -> 484.93151 | Q15: =+F15/$Z$5 -> 501.36986 | R15: =+G15/$Z$5 -> 517.80822 | S15: =+H15/$Z$5 -> 534.24658 | T15: =+I15/$Z$5 -> 550.68493 | U15: =+J15/$Z$5 -> 567.12329 | ... W15: =+L15/$Z$5 -> 600
A16: Tenure Track - high rate | B16: =_xlfn.XLOOKUP(Tabel12[[#This Row],[VIP]],Tabel19[Job functions],Tabel19[Column1],"",0)&"" | C16: 57000 | D16: =ROUNDUP(+C16*$Z$3,-3) -> 59000 | E16: =ROUNDUP(+D16*$Z$3,-3) -> 61000 | F16: =ROUNDUP(+E16*$Z$3,-3) -> 63000 | G16: =ROUNDUP(+F16*$Z$3,-3) -> 65000 | H16: =ROUNDUP(+G16*$Z$3,-3) -> 67000 | I16: =ROUNDUP(+H16*$Z$3,-3) -> 69000 | J16: =ROUNDUP(+I16*$Z$3,-3) -> 71000 | K16: =ROUNDUP(+J16*$Z$3,-3) -> 73000 | L16: =ROUNDUP(+K16*$Z$3,-3) -> 75000 | N16: =+C16/$Z$5 -> 468.49315 | O16: =+D16/$Z$5 -> 484.93151 | P16: =+E16/$Z$5 -> 501.36986 | Q16: =+F16/$Z$5 -> 517.80822 | R16: =+G16/$Z$5 -> 534.24658 | S16: =+H16/$Z$5 -> 550.68493 | T16: =+I16/$Z$5 -> 567.12329 | U16: =+J16/$Z$5 -> 583.56164 | ... W16: =+L16/$Z$5 -> 616.43836
A17: Tenure Track - avr. rate | B17: =_xlfn.XLOOKUP(Tabel12[[#This Row],[VIP]],Tabel19[Job functions],Tabel19[Column1],"",0)&"" | C17: 55000 | D17: =ROUNDUP(+C17*$Z$3,-3) -> 57000 | E17: =ROUNDUP(+D17*$Z$3,-3) -> 59000 | F17: =ROUNDUP(+E17*$Z$3,-3) -> 61000 | G17: =ROUNDUP(+F17*$Z$3,-3) -> 63000 | H17: =ROUNDUP(+G17*$Z$3,-3) -> 65000 | I17: =ROUNDUP(+H17*$Z$3,-3) -> 67000 | J17: =ROUNDUP(+I17*$Z$3,-3) -> 69000 | K17: =ROUNDUP(+J17*$Z$3,-3) -> 71000 | L17: =ROUNDUP(+K17*$Z$3,-3) -> 73000 | N17: =+C17/$Z$5 -> 452.05479 | O17: =+D17/$Z$5 -> 468.49315 | P17: =+E17/$Z$5 -> 484.93151 | Q17: =+F17/$Z$5 -> 501.36986 | R17: =+G17/$Z$5 -> 517.80822 | S17: =+H17/$Z$5 -> 534.24658 | T17: =+I17/$Z$5 -> 550.68493 | U17: =+J17/$Z$5 -> 567.12329 | ... W17: =+L17/$Z$5 -> 600
... A27: Post Doc abroad (Applicant, no project supplement) - low rate | B27: =_xlfn.XLOOKUP(Tabel12[[#This Row],[VIP]],Tabel19[Job functions],Tabel19[Column1],"",0)&"" | C27: 53000 | D27: =ROUNDUP(+C27*$Z$3,-3) -> 55000 | E27: =ROUNDUP(+D27*$Z$3,-3) -> 57000 | F27: =ROUNDUP(+E27*$Z$3,-3) -> 59000 | G27: =ROUNDUP(+F27*$Z$3,-3) -> 61000 | H27: =ROUNDUP(+G27*$Z$3,-3) -> 63000 | I27: =ROUNDUP(+H27*$Z$3,-3) -> 65000 | J27: =ROUNDUP(+I27*$Z$3,-3) -> 67000 | K27: =ROUNDUP(+J27*$Z$3,-3) -> 69000 | L27: =ROUNDUP(+K27*$Z$3,-3) -> 71000 | N27: =+C27/$Z$5 -> 435.61644 | O27: =+D27/$Z$5 -> 452.05479 | P27: =+E27/$Z$5 -> 468.49315 | Q27: =+F27/$Z$5 -> 484.93151 | R27: =+G27/$Z$5 -> 501.36986 | S27: =+H27/$Z$5 -> 517.80822 | T27: =+I27/$Z$5 -> 534.24658 | U27: =+J27/$Z$5 -> 550.68493 | ... W27: =+L27/$Z$5 -> 583.56164
B28: =_xlfn.XLOOKUP(Tabel12[[#This Row],[VIP]],Tabel19[Job functions],Tabel19[Column1],"",0)&"" | C28: 0 | D28: =ROUNDUP(+C28*$Z$3,-3) -> 0 | E28: =ROUNDUP(+D28*$Z$3,-3) -> 0 | F28: =ROUNDUP(+E28*$Z$3,-3) -> 0 | G28: =ROUNDUP(+F28*$Z$3,-3) -> 0 | H28: =ROUNDUP(+G28*$Z$3,-3) -> 0 | I28: =ROUNDUP(+H28*$Z$3,-3) -> 0 | J28: =ROUNDUP(+I28*$Z$3,-3) -> 0 | K28: =ROUNDUP(+J28*$Z$3,-3) -> 0 | L28: =ROUNDUP(+K28*$Z$3,-3) -> 0 | N28: =+C28/$Z$5 -> 0 | O28: =+D28/$Z$5 -> 0 | P28: =+E28/$Z$5 -> 0 | Q28: =+F28/$Z$5 -> 0 | R28: =+G28/$Z$5 -> 0 | S28: =+H28/$Z$5 -> 0 | T28: =+I28/$Z$5 -> 0 | U28: =+J28/$Z$5 -> 0 | ... W28: =+L28/$Z$5 -> 0
B29: =_xlfn.XLOOKUP(Tabel12[[#This Row],[VIP]],Tabel19[Job functions],Tabel19[Column1],"",0)&"" | C29: 0 | D29: =ROUNDUP(+C29*$Z$3,-3) -> 0 | E29: =ROUNDUP(+D29*$Z$3,-3) -> 0 | F29: =ROUNDUP(+E29*$Z$3,-3) -> 0 | G29: =ROUNDUP(+F29*$Z$3,-3) -> 0 | H29: =ROUNDUP(+G29*$Z$3,-3) -> 0 | I29: =ROUNDUP(+H29*$Z$3,-3) -> 0 | J29: =ROUNDUP(+I29*$Z$3,-3) -> 0 | K29: =ROUNDUP(+J29*$Z$3,-3) -> 0 | L29: =ROUNDUP(+K29*$Z$3,-3) -> 0 | N29: =+C29/$Z$5 -> 0 | O29: =+D29/$Z$5 -> 0 | P29: =+E29/$Z$5 -> 0 | Q29: =+F29/$Z$5 -> 0 | R29: =+G29/$Z$5 -> 0 | S29: =+H29/$Z$5 -> 0 | T29: =+I29/$Z$5 -> 0 | U29: =+J29/$Z$5 -> 0 | ... W29: =+L29/$Z$5 -> 0
B30: =_xlfn.XLOOKUP(Tabel12[[#This Row],[VIP]],Tabel19[Job functions],Tabel19[Column1],"",0)&"" | C30: 0 | D30: =ROUNDUP(+C30*$Z$3,-3) -> 0 | E30: =ROUNDUP(+D30*$Z$3,-3) -> 0 | F30: =ROUNDUP(+E30*$Z$3,-3) -> 0 | G30: =ROUNDUP(+F30*$Z$3,-3) -> 0 | H30: =ROUNDUP(+G30*$Z$3,-3) -> 0 | I30: =ROUNDUP(+H30*$Z$3,-3) -> 0 | J30: =ROUNDUP(+I30*$Z$3,-3) -> 0 | K30: =ROUNDUP(+J30*$Z$3,-3) -> 0 | L30: =ROUNDUP(+K30*$Z$3,-3) -> 0 | N30: =+C30/$Z$5 -> 0 | O30: =+D30/$Z$5 -> 0 | P30: =+E30/$Z$5 -> 0 | Q30: =+F30/$Z$5 -> 0 | R30: =+G30/$Z$5 -> 0 | S30: =+H30/$Z$5 -> 0 | T30: =+I30/$Z$5 -> 0 | U30: =+J30/$Z$5 -> 0 | ... W30: =+L30/$Z$5 -> 0
A32: TAP | C32: Column1 | D32: Hvis der tastes en medarbejder inkl. Kostpris ind, så skriv Laborant, Tekniker eller TAP/Ørig kandidatuddannet I kolonne B, idet den så medtages I forskningsadministrationsberegningen
A33: "Choose job position" | B33: =_xlfn.XLOOKUP(Tabel13[[#This Row],[TAP]],Tabel19[Job functions],Tabel19[Column1],"",0)&""
A34: Student help | B34: =_xlfn.XLOOKUP(Tabel13[[#This Row],[TAP]],Tabel19[Job functions],Tabel19[Column1],"",0)&"" | C34: 25000 | D34: =ROUNDUP(+C34*$Z$3,-2) -> 25700 | E34: =ROUNDUP(+D34*$Z$3,-2) -> 26400 | F34: =ROUNDUP(+E34*$Z$3,-2) -> 27100 | G34: =ROUNDUP(+F34*$Z$3,-2) -> 27800 | H34: =ROUNDUP(+G34*$Z$3,-2) -> 28500 | I34: =ROUNDUP(+H34*$Z$3,-2) -> 29300 | J34: =ROUNDUP(+I34*$Z$3,-2) -> 30100 | K34: =ROUNDUP(+J34*$Z$3,-2) -> 30900 | L34: =ROUNDUP(+K34*$Z$3,-2) -> 31700 | N34: =+C34/$Z$5 -> 205.47945 | O34: =+D34/$Z$5 -> 211.23288 | P34: =+E34/$Z$5 -> 216.9863 | Q34: =+F34/$Z$5 -> 222.73973 | R34: =+G34/$Z$5 -> 228.49315 | S34: =+H34/$Z$5 -> 234.24658 | T34: =+I34/$Z$5 -> 240.82192 | U34: =+J34/$Z$5 -> 247.39726 | ... W34: =+L34/$Z$5 -> 260.54795
A35: TAP/Other masters degree | B35: =_xlfn.XLOOKUP(Tabel13[[#This Row],[TAP]],Tabel19[Job functions],Tabel19[Column1],"",0)&"" -> TAP/Other Masters degree | C35: 59000 | D35: =ROUNDUP(+C35*$Z$3,-2) -> 60500 | E35: =ROUNDUP(+D35*$Z$3,-2) -> 62100 | F35: =ROUNDUP(+E35*$Z$3,-2) -> 63700 | G35: =ROUNDUP(+F35*$Z$3,-2) -> 65300 | H35: =ROUNDUP(+G35*$Z$3,-2) -> 67000 | I35: =ROUNDUP(+H35*$Z$3,-2) -> 68700 | J35: =ROUNDUP(+I35*$Z$3,-2) -> 70500 | K35: =ROUNDUP(+J35*$Z$3,-2) -> 72300 | L35: =ROUNDUP(+K35*$Z$3,-2) -> 74200 | N35: =+C35/$Z$5 -> 484.93151 | O35: =+D35/$Z$5 -> 497.26027 | P35: =+E35/$Z$5 -> 510.41096 | Q35: =+F35/$Z$5 -> 523.56164 | R35: =+G35/$Z$5 -> 536.71233 | S35: =+H35/$Z$5 -> 550.68493 | T35: =+I35/$Z$5 -> 564.65753 | U35: =+J35/$Z$5 -> 579.45205 | ... W35: =+L35/$Z$5 -> 609.86301
A36: Data/IT employee | B36: =_xlfn.XLOOKUP(Tabel13[[#This Row],[TAP]],Tabel19[Job functions],Tabel19[Column1],"",0)&"" | C36: 57000 | D36: =ROUNDUP(+C36*$Z$3,-2) -> 58500 | E36: =ROUNDUP(+D36*$Z$3,-2) -> 60000 | F36: =ROUNDUP(+E36*$Z$3,-2) -> 61500 | G36: =ROUNDUP(+F36*$Z$3,-2) -> 63100 | H36: =ROUNDUP(+G36*$Z$3,-2) -> 64700 | I36: =ROUNDUP(+H36*$Z$3,-2) -> 66400 | J36: =ROUNDUP(+I36*$Z$3,-2) -> 68100 | K36: =ROUNDUP(+J36*$Z$3,-2) -> 69900 | L36: =ROUNDUP(+K36*$Z$3,-2) -> 71700 | N36: =+C36/$Z$5 -> 468.49315 | O36: =+D36/$Z$5 -> 480.82192 | P36: =+E36/$Z$5 -> 493.15068 | Q36: =+F36/$Z$5 -> 505.47945 | R36: =+G36/$Z$5 -> 518.63014 | S36: =+H36/$Z$5 -> 531.78082 | T36: =+I36/$Z$5 -> 545.75342 | U36: =+J36/$Z$5 -> 559.72603 | ... W36: =+L36/$Z$5 -> 589.31507
A37: Laboratory technician - high rate | B37: =_xlfn.XLOOKUP(Tabel13[[#This Row],[TAP]],Tabel19[Job functions],Tabel19[Column1],"",0)&"" -> Laboratory technician | C37: 48000 | D37: =ROUNDUP(+C37*$Z$3,-2) -> 49200 | E37: =ROUNDUP(+D37*$Z$3,-2) -> 50500 | F37: =ROUNDUP(+E37*$Z$3,-2) -> 51800 | G37: =ROUNDUP(+F37*$Z$3,-2) -> 53100 | H37: =ROUNDUP(+G37*$Z$3,-2) -> 54500 | I37: =ROUNDUP(+H37*$Z$3,-2) -> 55900 | J37: =ROUNDUP(+I37*$Z$3,-2) -> 57300 | K37: =ROUNDUP(+J37*$Z$3,-2) -> 58800 | L37: =ROUNDUP(+K37*$Z$3,-2) -> 60300 | N37: =+C37/$Z$5 -> 394.52055 | O37: =+D37/$Z$5 -> 404.38356 | P37: =+E37/$Z$5 -> 415.06849 | Q37: =+F37/$Z$5 -> 425.75342 | R37: =+G37/$Z$5 -> 436.43836 | S37: =+H37/$Z$5 -> 447.94521 | T37: =+I37/$Z$5 -> 459.45205 | U37: =+J37/$Z$5 -> 470.9589 | ... W37: =+L37/$Z$5 -> 495.61644
A38: Laboratory technician - avr. rate | B38: =_xlfn.XLOOKUP(Tabel13[[#This Row],[TAP]],Tabel19[Job functions],Tabel19[Column1],"",0)&"" -> Laboratory technician | C38: 44000 | D38: =ROUNDUP(+C38*$Z$3,-2) -> 45100 | E38: =ROUNDUP(+D38*$Z$3,-2) -> 46300 | F38: =ROUNDUP(+E38*$Z$3,-2) -> 47500 | G38: =ROUNDUP(+F38*$Z$3,-2) -> 48700 | H38: =ROUNDUP(+G38*$Z$3,-2) -> 50000 | I38: =ROUNDUP(+H38*$Z$3,-2) -> 51300 | J38: =ROUNDUP(+I38*$Z$3,-2) -> 52600 | K38: =ROUNDUP(+J38*$Z$3,-2) -> 54000 | L38: =ROUNDUP(+K38*$Z$3,-2) -> 55400 | N38: =+C38/$Z$5 -> 361.64384 | O38: =+D38/$Z$5 -> 370.68493 | P38: =+E38/$Z$5 -> 380.54795 | Q38: =+F38/$Z$5 -> 390.41096 | R38: =+G38/$Z$5 -> 400.27397 | S38: =+H38/$Z$5 -> 410.9589 | T38: =+I38/$Z$5 -> 421.64384 | U38: =+J38/$Z$5 -> 432.32877 | ... W38: =+L38/$Z$5 -> 455.34247
A39: Laboratory technician - low rate | B39: =_xlfn.XLOOKUP(Tabel13[[#This Row],[TAP]],Tabel19[Job functions],Tabel19[Column1],"",0)&"" -> Laboratory technician | C39: 41000 | D39: =ROUNDUP(+C39*$Z$3,-2) -> 42100 | E39: =ROUNDUP(+D39*$Z$3,-2) -> 43200 | F39: =ROUNDUP(+E39*$Z$3,-2) -> 44300 | G39: =ROUNDUP(+F39*$Z$3,-2) -> 45500 | H39: =ROUNDUP(+G39*$Z$3,-2) -> 46700 | I39: =ROUNDUP(+H39*$Z$3,-2) -> 47900 | J39: =ROUNDUP(+I39*$Z$3,-2) -> 49100 | K39: =ROUNDUP(+J39*$Z$3,-2) -> 50400 | L39: =ROUNDUP(+K39*$Z$3,-2) -> 51700 | N39: =+C39/$Z$5 -> 336.9863 | O39: =+D39/$Z$5 -> 346.0274 | P39: =+E39/$Z$5 -> 355.06849 | Q39: =+F39/$Z$5 -> 364.10959 | R39: =+G39/$Z$5 -> 373.9726 | S39: =+H39/$Z$5 -> 383.83562 | T39: =+I39/$Z$5 -> 393.69863 | U39: =+J39/$Z$5 -> 403.56164 | ... W39: =+L39/$Z$5 -> 424.93151
A40: Technician - high rate | B40: =_xlfn.XLOOKUP(Tabel13[[#This Row],[TAP]],Tabel19[Job functions],Tabel19[Column1],"",0)&"" -> Technician | C40: 53000 | D40: =ROUNDUP(+C40*$Z$3,-2) -> 54400 | E40: =ROUNDUP(+D40*$Z$3,-2) -> 55800 | F40: =ROUNDUP(+E40*$Z$3,-2) -> 57200 | G40: =ROUNDUP(+F40*$Z$3,-2) -> 58700 | H40: =ROUNDUP(+G40*$Z$3,-2) -> 60200 | I40: =ROUNDUP(+H40*$Z$3,-2) -> 61800 | J40: =ROUNDUP(+I40*$Z$3,-2) -> 63400 | K40: =ROUNDUP(+J40*$Z$3,-2) -> 65000 | L40: =ROUNDUP(+K40*$Z$3,-2) -> 66700 | N40: =+C40/$Z$5 -> 435.61644 | O40: =+D40/$Z$5 -> 447.12329 | P40: =+E40/$Z$5 -> 458.63014 | Q40: =+F40/$Z$5 -> 470.13699 | R40: =+G40/$Z$5 -> 482.46575 | S40: =+H40/$Z$5 -> 494.79452 | T40: =+I40/$Z$5 -> 507.94521 | U40: =+J40/$Z$5 -> 521.09589 | ... W40: =+L40/$Z$5 -> 548.21918
A41: Technician - avr. rate | B41: =_xlfn.XLOOKUP(Tabel13[[#This Row],[TAP]],Tabel19[Job functions],Tabel19[Column1],"",0)&"" -> Technician | C41: 50000 | D41: =ROUNDUP(+C41*$Z$3,-2) -> 51300 | E41: =ROUNDUP(+D41*$Z$3,-2) -> 52600 | F41: =ROUNDUP(+E41*$Z$3,-2) -> 54000 | G41: =ROUNDUP(+F41*$Z$3,-2) -> 55400 | H41: =ROUNDUP(+G41*$Z$3,-2) -> 56800 | I41: =ROUNDUP(+H41*$Z$3,-2) -> 58300 | J41: =ROUNDUP(+I41*$Z$3,-2) -> 59800 | K41: =ROUNDUP(+J41*$Z$3,-2) -> 61300 | L41: =ROUNDUP(+K41*$Z$3,-2) -> 62900 | N41: =+C41/$Z$5 -> 410.9589 | O41: =+D41/$Z$5 -> 421.64384 | P41: =+E41/$Z$5 -> 432.32877 | Q41: =+F41/$Z$5 -> 443.83562 | R41: =+G41/$Z$5 -> 455.34247 | S41: =+H41/$Z$5 -> 466.84932 | T41: =+I41/$Z$5 -> 479.17808 | U41: =+J41/$Z$5 -> 491.50685 | ... W41: =+L41/$Z$5 -> 516.9863
A42: Technician - low rate | B42: =_xlfn.XLOOKUP(Tabel13[[#This Row],[TAP]],Tabel19[Job functions],Tabel19[Column1],"",0)&"" -> Technician | C42: 45000 | D42: =ROUNDUP(+C42*$Z$3,-2) -> 46200 | E42: =ROUNDUP(+D42*$Z$3,-2) -> 47400 | F42: =ROUNDUP(+E42*$Z$3,-2) -> 48600 | G42: =ROUNDUP(+F42*$Z$3,-2) -> 49900 | H42: =ROUNDUP(+G42*$Z$3,-2) -> 51200 | I42: =ROUNDUP(+H42*$Z$3,-2) -> 52500 | J42: =ROUNDUP(+I42*$Z$3,-2) -> 53900 | K42: =ROUNDUP(+J42*$Z$3,-2) -> 55300 | L42: =ROUNDUP(+K42*$Z$3,-2) -> 56700 | N42: =+C42/$Z$5 -> 369.86301 | O42: =+D42/$Z$5 -> 379.72603 | P42: =+E42/$Z$5 -> 389.58904 | Q42: =+F42/$Z$5 -> 399.45205 | R42: =+G42/$Z$5 -> 410.13699 | S42: =+H42/$Z$5 -> 420.82192 | T42: =+I42/$Z$5 -> 431.50685 | U42: =+J42/$Z$5 -> 443.0137 | ... W42: =+L42/$Z$5 -> 466.0274
A43: Other TAP - avr. rate | B43: =_xlfn.XLOOKUP(Tabel13[[#This Row],[TAP]],Tabel19[Job functions],Tabel19[Column1],"",0)&"" | C43: 47000 | D43: =ROUNDUP(+C43*$Z$3,-2) -> 48200 | E43: =ROUNDUP(+D43*$Z$3,-2) -> 49500 | F43: =ROUNDUP(+E43*$Z$3,-2) -> 50800 | G43: =ROUNDUP(+F43*$Z$3,-2) -> 52100 | H43: =ROUNDUP(+G43*$Z$3,-2) -> 53500 | I43: =ROUNDUP(+H43*$Z$3,-2) -> 54900 | J43: =ROUNDUP(+I43*$Z$3,-2) -> 56300 | K43: =ROUNDUP(+J43*$Z$3,-2) -> 57800 | L43: =ROUNDUP(+K43*$Z$3,-2) -> 59300 | N43: =+C43/$Z$5 -> 386.30137 | O43: =+D43/$Z$5 -> 396.16438 | P43: =+E43/$Z$5 -> 406.84932 | Q43: =+F43/$Z$5 -> 417.53425 | R43: =+G43/$Z$5 -> 428.21918 | S43: =+H43/$Z$5 -> 439.72603 | T43: =+I43/$Z$5 -> 451.23288 | U43: =+J43/$Z$5 -> 462.73973 | ... W43: =+L43/$Z$5 -> 487.39726
A44: Secretary | B44: =_xlfn.XLOOKUP(Tabel13[[#This Row],[TAP]],Tabel19[Job functions],Tabel19[Column1],"",0)&"" | C44: 46000 | D44: =ROUNDUP(+C44*$Z$3,-2) -> 47200 | E44: =ROUNDUP(+D44*$Z$3,-2) -> 48400 | F44: =ROUNDUP(+E44*$Z$3,-2) -> 49700 | G44: =ROUNDUP(+F44*$Z$3,-2) -> 51000 | H44: =ROUNDUP(+G44*$Z$3,-2) -> 52300 | I44: =ROUNDUP(+H44*$Z$3,-2) -> 53700 | J44: =ROUNDUP(+I44*$Z$3,-2) -> 55100 | K44: =ROUNDUP(+J44*$Z$3,-2) -> 56500 | L44: =ROUNDUP(+K44*$Z$3,-2) -> 58000 | N44: =+C44/$Z$5 -> 378.08219 | O44: =+D44/$Z$5 -> 387.94521 | P44: =+E44/$Z$5 -> 397.80822 | Q44: =+F44/$Z$5 -> 408.49315 | R44: =+G44/$Z$5 -> 419.17808 | S44: =+H44/$Z$5 -> 429.86301 | T44: =+I44/$Z$5 -> 441.36986 | U44: =+J44/$Z$5 -> 452.87671 | ... W44: =+L44/$Z$5 -> 476.71233
A45: Special/manager consultant- high rate | B45: =_xlfn.XLOOKUP(Tabel13[[#This Row],[TAP]],Tabel19[Job functions],Tabel19[Column1],"",0)&"" | C45: 69000 | D45: =ROUNDUP(+C45*$Z$3,-2) -> 70800 | E45: =ROUNDUP(+D45*$Z$3,-2) -> 72600 | F45: =ROUNDUP(+E45*$Z$3,-2) -> 74500 | G45: =ROUNDUP(+F45*$Z$3,-2) -> 76400 | H45: =ROUNDUP(+G45*$Z$3,-2) -> 78400 | I45: =ROUNDUP(+H45*$Z$3,-2) -> 80400 | J45: =ROUNDUP(+I45*$Z$3,-2) -> 82500 | K45: =ROUNDUP(+J45*$Z$3,-2) -> 84600 | L45: =ROUNDUP(+K45*$Z$3,-2) -> 86800 | N45: =+C45/$Z$5 -> 567.12329 | O45: =+D45/$Z$5 -> 581.91781 | P45: =+E45/$Z$5 -> 596.71233 | Q45: =+F45/$Z$5 -> 612.32877 | R45: =+G45/$Z$5 -> 627.94521 | S45: =+H45/$Z$5 -> 644.38356 | T45: =+I45/$Z$5 -> 660.82192 | U45: =+J45/$Z$5 -> 678.08219 | ... W45: =+L45/$Z$5 -> 713.42466
... A47: Special/manager consultant - low rate | B47: =_xlfn.XLOOKUP(Tabel13[[#This Row],[TAP]],Tabel19[Job functions],Tabel19[Column1],"",0)&"" | C47: 62000 | D47: =ROUNDUP(+C47*$Z$3,-2) -> 63600 | E47: =ROUNDUP(+D47*$Z$3,-2) -> 65200 | F47: =ROUNDUP(+E47*$Z$3,-2) -> 66900 | G47: =ROUNDUP(+F47*$Z$3,-2) -> 68600 | H47: =ROUNDUP(+G47*$Z$3,-2) -> 70400 | I47: =ROUNDUP(+H47*$Z$3,-2) -> 72200 | J47: =ROUNDUP(+I47*$Z$3,-2) -> 74100 | K47: =ROUNDUP(+J47*$Z$3,-2) -> 76000 | L47: =ROUNDUP(+K47*$Z$3,-2) -> 77900 | N47: =+C47/$Z$5 -> 509.58904 | O47: =+D47/$Z$5 -> 522.73973 | P47: =+E47/$Z$5 -> 535.89041 | Q47: =+F47/$Z$5 -> 549.86301 | R47: =+G47/$Z$5 -> 563.83562 | S47: =+H47/$Z$5 -> 578.63014 | T47: =+I47/$Z$5 -> 593.42466 | U47: =+J47/$Z$5 -> 609.0411 | ... W47: =+L47/$Z$5 -> 640.27397
B48: =_xlfn.XLOOKUP(Tabel13[[#This Row],[TAP]],Tabel19[Job functions],Tabel19[Column1],"",0)&"" | C48: 0 | D48: =ROUNDUP(+C48*$Z$3,-2) -> 0 | E48: =ROUNDUP(+D48*$Z$3,-2) -> 0 | F48: =ROUNDUP(+E48*$Z$3,-2) -> 0 | G48: =ROUNDUP(+F48*$Z$3,-2) -> 0 | H48: =ROUNDUP(+G48*$Z$3,-2) -> 0 | I48: =ROUNDUP(+H48*$Z$3,-2) -> 0 | J48: =ROUNDUP(+I48*$Z$3,-2) -> 0 | K48: =ROUNDUP(+J48*$Z$3,-2) -> 0 | L48: =ROUNDUP(+K48*$Z$3,-2) -> 0 | N48: =+C48/$Z$5 -> 0 | O48: =+D48/$Z$5 -> 0 | P48: =+E48/$Z$5 -> 0 | Q48: =+F48/$Z$5 -> 0 | R48: =+G48/$Z$5 -> 0 | S48: =+H48/$Z$5 -> 0 | T48: =+I48/$Z$5 -> 0 | U48: =+J48/$Z$5 -> 0 | ... W48: =+L48/$Z$5 -> 0
B49: =_xlfn.XLOOKUP(Tabel13[[#This Row],[TAP]],Tabel19[Job functions],Tabel19[Column1],"",0)&"" | C49: 0 | D49: =ROUNDUP(+C49*$Z$3,-2) -> 0 | E49: =ROUNDUP(+D49*$Z$3,-2) -> 0 | F49: =ROUNDUP(+E49*$Z$3,-2) -> 0 | G49: =ROUNDUP(+F49*$Z$3,-2) -> 0 | H49: =ROUNDUP(+G49*$Z$3,-2) -> 0 | I49: =ROUNDUP(+H49*$Z$3,-2) -> 0 | J49: =ROUNDUP(+I49*$Z$3,-2) -> 0 | K49: =ROUNDUP(+J49*$Z$3,-2) -> 0 | L49: =ROUNDUP(+K49*$Z$3,-2) -> 0 | N49: =+C49/$Z$5 -> 0 | O49: =+D49/$Z$5 -> 0 | P49: =+E49/$Z$5 -> 0 | Q49: =+F49/$Z$5 -> 0 | R49: =+G49/$Z$5 -> 0 | S49: =+H49/$Z$5 -> 0 | T49: =+I49/$Z$5 -> 0 | U49: =+J49/$Z$5 -> 0 | ... W49: =+L49/$Z$5 -> 0
B50: =_xlfn.XLOOKUP(Tabel13[[#This Row],[TAP]],Tabel19[Job functions],Tabel19[Column1],"",0)&"" | C50: 0 | D50: =ROUNDUP(+C50*$Z$3,-2) -> 0 | E50: =ROUNDUP(+D50*$Z$3,-2) -> 0 | F50: =ROUNDUP(+E50*$Z$3,-2) -> 0 | G50: =ROUNDUP(+F50*$Z$3,-2) -> 0 | H50: =ROUNDUP(+G50*$Z$3,-2) -> 0 | I50: =ROUNDUP(+H50*$Z$3,-2) -> 0 | J50: =ROUNDUP(+I50*$Z$3,-2) -> 0 | K50: =ROUNDUP(+J50*$Z$3,-2) -> 0 | L50: =ROUNDUP(+K50*$Z$3,-2) -> 0 | N50: =+C50/$Z$5 -> 0 | O50: =+D50/$Z$5 -> 0 | P50: =+E50/$Z$5 -> 0 | Q50: =+F50/$Z$5 -> 0 | R50: =+G50/$Z$5 -> 0 | S50: =+H50/$Z$5 -> 0 | T50: =+I50/$Z$5 -> 0 | U50: =+J50/$Z$5 -> 0 | ... W50: =+L50/$Z$5 -> 0
B51: =_xlfn.XLOOKUP(Tabel13[[#This Row],[TAP]],Tabel19[Job functions],Tabel19[Column1],"",0)&"" | C51: 0 | D51: =ROUNDUP(+C51*$Z$3,-2) -> 0 | E51: =ROUNDUP(+D51*$Z$3,-2) -> 0 | F51: =ROUNDUP(+E51*$Z$3,-2) -> 0 | G51: =ROUNDUP(+F51*$Z$3,-2) -> 0 | H51: =ROUNDUP(+G51*$Z$3,-2) -> 0 | I51: =ROUNDUP(+H51*$Z$3,-2) -> 0 | J51: =ROUNDUP(+I51*$Z$3,-2) -> 0 | K51: =ROUNDUP(+J51*$Z$3,-2) -> 0 | L51: =ROUNDUP(+K51*$Z$3,-2) -> 0 | N51: =+C51/$Z$5 -> 0 | O51: =+D51/$Z$5 -> 0 | P51: =+E51/$Z$5 -> 0 | Q51: =+F51/$Z$5 -> 0 | R51: =+G51/$Z$5 -> 0 | S51: =+H51/$Z$5 -> 0 | T51: =+I51/$Z$5 -> 0 | U51: =+J51/$Z$5 -> 0 | ... W51: =+L51/$Z$5 -> 0
...

Sheet GrantSource
A1: GrantSource | B1: GrantSourceExtra | C1: GrantSourceUdvidet
A2: 15. Juni Fonden | C2: 15. Juni Fonden ()
A3: A.J. Andersen og Hustrus Fond | C3: A.J. Andersen og Hustrus Fond ()
A4: A.P. Møller og Hustrus Fond | B4: A.P. Møller and Wife's Foundation | C4: A.P. Møller og Hustrus Fond (A.P. Møller and Wife's Foundation)
A5: ASC Utrecht University | C5: ASC Utrecht University ()
A6: AU strategiske midler | B6: Aarhus University strategic funds | C6: AU strategiske midler (Aarhus University strategic funds)
A7: Aage V. Jensen Naturfond | C7: Aage V. Jensen Naturfond ()
A8: Aage V. Jensens Fonde | C8: Aage V. Jensens Fonde ()
A9: Aage og Johanne Louis-Hansens Fond | C9: Aage og Johanne Louis-Hansens Fond ()
A10: Aarhus Institute of Advanced Studies | B10: AIAS | C10: Aarhus Institute of Advanced Studies (AIAS)
A11: Aarhus Kommune | C11: Aarhus Kommune ()
A12: Aarhus Universitet | B12: AU | C12: Aarhus Universitet (AU)
A13: Aarhus Universitets Forskningsfond | B13: Aarhus University Research Foundation, AUFF | C13: Aarhus Universitets Forskningsfond (Aarhus University Research Foundation, AUFF)
A14: Aarhus Universitetshospital | B14: Aarhus University Hospital | C14: Aarhus Universitetshospital (Aarhus University Hospital)
A15: Aase og Ejnar Danielsens Fond | C15: Aase og Ejnar Danielsens Fond ()
A16: Actinobac Biomed Inc. | C16: Actinobac Biomed Inc. ()
A17: Advanced Research Invention Agency | B17: ARIA | C17: Advanced Research Invention Agency (ARIA)
A18: Agouron Institute | C18: Agouron Institute ()
A19: Agria | C19: Agria ()
A20: Agro Business Park A/S | C20: Agro Business Park A/S ()
A21: AgroParisTech | C21: AgroParisTech ()
A22: Aktieselskabet Dampskibsselskabet Orients Fond | C22: Aktieselskabet Dampskibsselskabet Orients Fond ()
A23: Alexion Pharmaceuticals | C23: Alexion Pharmaceuticals ()
A24: AlgeCenter Danmark | C24: AlgeCenter Danmark ()
A25: Aliophtha A/S | C25: Aliophtha A/S ()
A26: Alzheimer's Association | C26: Alzheimer's Association ()
A27: Angely Yeast | C27: Angely Yeast ()
A28: Apple EMEIA Accounts payable | C28: Apple EMEIA Accounts payable ()
A29: Arcedi Biotech ApS | C29: Arcedi Biotech ApS ()
... A31: Arts & Humanities Research Council | C31: Arts & Humanities Research Council ()
A32: Arvid Nilssons Fond | B32: The Arvid Nilssons Foundation | C32: Arvid Nilssons Fond (The Arvid Nilssons Foundation)
A33: Augustinus Fonden | B33: The Augustinus Foundation | C33: Augustinus Fonden (The Augustinus Foundation)
A34: Autism Speaks | C34: Autism Speaks ()
A35: Axel Muusfeldts Fond | C35: Axel Muusfeldts Fond ()
A36: BASF A/S | C36: BASF A/S ()
A37: BETA.HEALTH - AUH | C37: BETA.HEALTH - AUH ()
A38: BONUS Science for a better | C38: BONUS Science for a better ()
A39: BRGM | C39: BRGM ()
A40: Bayer A/S | C40: Bayer A/S ()
A41: Bayer AB | C41: Bayer AB ()
...

Sheet Instrument
A1: GrantSource | B1: GrantSourcesExtra | C1: GrantSourceUdvidet | D1: Instrument
A2: Aarhus Kommune | C2: Aarhus Kommune ()
A3: Aarhus Universitet | B3: AU | C3: Aarhus Universitet (AU) | D3: AU Connect | F3: {=IFERROR(_xlfn.UNIQUE(_xlfn._xlws.FILTER(D:D,C:C='Cover letter'!C7)&_xlfn._xlws.FILTER(D:D,C:C='Cover letter ECE_MPE'!C7)),"")} | G3: <- denne formel bruges til at finde unikke instruments pba. valgt grant source i CL
A4: Aarhus Universitet | B4: AU | C4: Aarhus Universitet (AU) | D4: Bridge4Water
A5: Aarhus Universitet | B5: AU | C5: Aarhus Universitet (AU) | D5: CellFood
A6: Aarhus Universitet | B6: AU | C6: Aarhus Universitet (AU) | D6: CO2 Research Center, CORC
A7: Aarhus Universitet | B7: AU | C7: Aarhus Universitet (AU) | D7: Health-Tech Network Innovation Funding
A8: Danmarks Grundforskningsfond | B8: Danish National Research Foundation | C8: Danmarks Grundforskningsfond (Danish National Research Foundation) | D8: Centres of Excellence
A9: Danmarks Grundforskningsfond | B9: Danish National Research Foundation | C9: Danmarks Grundforskningsfond (Danish National Research Foundation) | D9: GROW
A10: Danmarks Grundforskningsfond | B10: Danish National Research Foundation | C10: Danmarks Grundforskningsfond (Danish National Research Foundation) | D10: Chair
A11: Forskningsrådet for Natur og Univers | B11: Danmarks Frie Forskningsråd, The Danish Research Council for Natural Sciences, DFF FNU | C11: Forskningsrådet for Natur og Univers (Danmarks Frie Forskningsråd, The Danish Research Council for Natural Sciences, DFF FNU) | D11: Danish ERC-programme
A12: Forskningsrådet for Natur og Univers | B12: Danmarks Frie Forskningsråd, The Danish Research Council for Natural Sciences, DFF FNU | C12: Forskningsrådet for Natur og Univers (Danmarks Frie Forskningsråd, The Danish Research Council for Natural Sciences, DFF FNU) | D12: Research projects 1
A13: Forskningsrådet for Natur og Univers | B13: Danmarks Frie Forskningsråd, The Danish Research Council for Natural Sciences, DFF FNU | C13: Forskningsrådet for Natur og Univers (Danmarks Frie Forskningsråd, The Danish Research Council for Natural Sciences, DFF FNU) | D13: Research projects 2
A14: Forskningsrådet for Natur og Univers | B14: Danmarks Frie Forskningsråd, The Danish Research Council for Natural Sciences, DFF FNU | C14: Forskningsrådet for Natur og Univers (Danmarks Frie Forskningsråd, The Danish Research Council for Natural Sciences, DFF FNU) | D14: Inge Lehmann
A15: Forskningsrådet for Natur og Univers | B15: Danmarks Frie Forskningsråd, The Danish Research Council for Natural Sciences, DFF FNU | C15: Forskningsrådet for Natur og Univers (Danmarks Frie Forskningsråd, The Danish Research Council for Natural Sciences, DFF FNU) | D15: International Postdoc
... A68: InnovationsFonden | B68: Innovation Fund Denmark | C68: InnovationsFonden (Innovation Fund Denmark) | D68: Innomission
A69: Civilstyrelsen | B69: Department of Civil Affairs | C69: Civilstyrelsen (Department of Civil Affairs)
A70: Danida | B70: Danish International Development Assistance | C70: Danida (Danish International Development Assistance)
A71: Danida Fellowship Centre | C71: Danida Fellowship Centre ()
A72: Danida Green Business Partnerships | B72: DGBP | C72: Danida Green Business Partnerships (DGBP)
A73: Danida Knowledge and Innovation Partnerships | C73: Danida Knowledge and Innovation Partnerships ()
A74: Danish Diabetes Academy | C74: Danish Diabetes Academy () | D74: PhD Scholarships
A75: Danish Diabetes Academy | C75: Danish Diabetes Academy () | D75: Postdoctoral Fellowships
A76: Danish Diabetes Academy | C76: Danish Diabetes Academy () | D76: Visiting Professorships
A77: Danish Diabetes Academy | C77: Danish Diabetes Academy () | D77: Workshops
A78: Danish e-infrastructure | C78: Danish e-infrastructure ()
A79: Dansk Center for Havforskning | C79: Dansk Center for Havforskning ()
A80: Planteafgiftsfonden | C80: Planteafgiftsfonden ()
A81: Danmarks Tekniske Universitet | B81: Technical University of Denmark | C81: Danmarks Tekniske Universitet (Technical University of Denmark)
A82: Danske Regioner | B82: Danish Regions | C82: Danske Regioner (Danish Regions)
A83: Det danske SDC-sekretariat | B83: The Danish SDC secretariat | C83: Det danske SDC-sekretariat (The Danish SDC secretariat)
A84: DIREC | B84: Digital Research Centre Denmark | C84: DIREC (Digital Research Centre Denmark)
A85: Energinet.dk | C85: Energinet.dk ()
A86: Energistyrelsen | B86: Danish Energy Agency | C86: Energistyrelsen (Danish Energy Agency)
A87: Erhvervsstyrelsen | B87: The Danish Business Authority | C87: Erhvervsstyrelsen (The Danish Business Authority)
A88: Erhvervsfremmestyrelsen | B88: the Danish Board of Business Development | C88: Erhvervsfremmestyrelsen (the Danish Board of Business Development) | D88: Biosolutions Zealand
A89: Erhvervsfremmestyrelsen | B89: the Danish Board of Business Development | C89: Erhvervsfremmestyrelsen (the Danish Board of Business Development) | D89: Food & Bio Cluster Denmark
A90: Erhvervsfremmestyrelsen | B90: the Danish Board of Business Development | C90: Erhvervsfremmestyrelsen (the Danish Board of Business Development) | D90: Klyngeprogram 2025-2028 Lifestyle and Design Cluster
A91: EUDP – Det Energiteknologiske Udviklings- og Demonstrationsprogram | B91: The EUDP secretariat | C91: EUDP – Det Energiteknologiske Udviklings- og Demonstrationsprogram (The EUDP secretariat)
A92: Fjerkræafgiftsfonden | B92: Danish Poultry Levy Fund | C92: Fjerkræafgiftsfonden (Danish Poultry Levy Fund)
...

Sheet Section Cover letter ING
A1: Department | B1: Section
A2: CS | B2: ADA | E2: {=_xlfn.UNIQUE(_xlfn._xlws.FILTER(B:B,A:A='Cover letter ECE_MPE'!E5))} -> 0 | F2: <- denne formel bruges til at finde unikke sektioner pba. valgt institut i CL
A3: CS | B3: CRC
A4: CS | B4: HCC
A5: CS | B5: PLS
A6: MBG | B6: Protein Sciences
A7: MBG | B7: RNA Biology and Innovation
A8: MBG | B8: Plant Molecular Biology
A9: MBG | B9: Neurobiology
A10: MBG | B10: Molecular Health
A11: MBG | B11: BiRC
A12: QGG | B12: Admin
A13: QGG | B13: AgroBioDiversity
A14: QGG | B14: Animal
... A20: QGG | B20: Phenomics
A21: GEO
A22: BIO
A23: PHYS
A24: CHEM
A25: MATH
A26: INANO
A27: AGRO | B27: ABD
A28: AGRO | B28: CGB
A29: AGRO | B29: CROP
A30: AGRO | B30: JORD
A31: AGRO | B31: JORNÆR
A32: AGRO | B32: KLIMA
A33: AGRO | B33: Land-CRAFT
A34: AGRO | B34: PLANMIK
A35: AGRO | B35: SYSTEM
A36: AGRO | B36: STAB
A37: ENVS | B37: ATMI
A38: ENVS | B38: ATMO
... A47: ANIVET | B47: CAF
A48: FOOD
A49: ECOS | B49: WildEco
A50: ECOS | B50: MarMam
A51: ECOS | B51: ArcEnv
A52: ECOS | B52: BioCon
A53: ECOS | B53: CatchEnv
...

Sheet Section Cover letter
A1: Department | B1: Section
A2: CS | B2: ADA | E2: {=_xlfn.UNIQUE(_xlfn._xlws.FILTER(B:B,A:A='Cover letter'!E5))} -> 0 | F2: <- denne formel bruges til at finde unikke sektioner pba. valgt institut i CL
A3: CS | B3: CRC
A4: CS | B4: HCC
A5: CS | B5: PLS
A6: MBG | B6: Protein Sciences
A7: MBG | B7: RNA Biology and Innovation
A8: MBG | B8: Plant Molecular Biology
A9: MBG | B9: Neurobiology
A10: MBG | B10: Molecular Health
A11: MBG | B11: BiRC
A12: QGG | B12: Admin
A13: QGG | B13: AgroBioDiversity
A14: QGG | B14: Animal
... A20: QGG | B20: Phenomics
A21: GEO
A22: BIO
A23: PHYS
A24: CHEM
A25: MATH
A26: INANO
A27: AGRO | B27: ABD
A28: AGRO | B28: CGB
A29: AGRO | B29: CROP
A30: AGRO | B30: JORD
A31: AGRO | B31: JORNÆR
A32: AGRO | B32: KLIMA
A33: AGRO | B33: Land-CRAFT
A34: AGRO | B34: PLANMIK
A35: AGRO | B35: SYSTEM
A36: AGRO | B36: STAB
A37: ENVS | B37: ATMI
A38: ENVS | B38: ATMO
... A47: ANIVET | B47: CAF
A48: FOOD
A49: ECOS | B49: WildEco
A50: ECOS | B50: MarMam
A51: ECOS | B51: ArcEnv
A52: ECOS | B52: BioCon
A53: ECOS | B53: CatchEnv
...

Sheet Economists
A1: AUID | B1: Name
A2: au82350 | B2: Anne Cathrine Lund Petersen
A3: au783390 | B3: Adis Ramic
A4: au813887 | B4: Akbar Arian
A5: au223105 | B5: Alice Mørup
A6: au505985 | B6: Allan Bøge Ochwat
A7: au526752 | B7: Alexia Lessing
A8: au401197 | B8: Anette Holm Lundgren
A9: au401218 | B9: Allan Otto Wagner
A10: au247341 | B10: Anita Porsdal
A11: au512150 | B11: Astrid Hulgaard Jørgensen
A12: au236849 | B12: Britt Sønberg Vilstrup
... A83: au759774 | B83: Trine Rom Engholm

Sheet Lister
A1: Rullelister
A3: Institute | B3: Long name | D3: Overhead calculated on | F3: Yearly hours | G3: Description | I3: Supplement to research administration calculated by | K3: Currency | M3: Operations | O3: Project-supplement/Bench Fee
A4: AGRO | B4: Department of Agroecology | D4: Salary | F4: 1300 | I4: Salary | K4: DKK | M4: Choose type of operations | O4: Project-supplement
A5: ANIVET | B5: Department of Animal and Veterinary Sciences | D5: Salary and operations | F5: 1460 | G5: AU Standard (to be used unless other is stated) | I5: Operations | K5: EUR | M5: Misc. Operation/purchases/Consumables | O5: Bench Fee
A6: BCE | B6: Department of Biological and Chemical Engineering | D6: Salary and operations excl. External assistance/consultants | F6: 1485 | G6: EU | I6: Salary and operations | M6: Travel | O6: None
A7: CAE | B7: Department of Civil and Architectural Engineering | D7: Salary and operations excl. Procurements and External assistance/consultants | F7: 1642 | G7: GUDP | I7: None | M7: Procurements
A8: DCA | B8: Danish Centre for Food and Agriculture | D8: Salary, operations and Bench Fee | F8: 15xx | G8: Interreg | M8: Depreciations
A9: DCE | B9: Danish Centre for Environment and Energy | D9: Operations | F9: 1460 | G9: Grand Solutions | M9: Scrap-value
A10: ECE | B10: Department of Electrical and Computer Engineering | F10: 1642 | G10: NIFA | M10: External assistance/consultants
A11: ECOS | B11: Department of Ecoscience | M11: Ph.D. Tuition Fee
A12: ENVS | B12: Department of Environmental Science | M12: Analysis external
A13: FOOD | B13: Department of Food Science | M13: Analysis internal
A14: ICROFS | B14: International Centre for Research in Organic Food Systems | M14: Field operations, Research stations
A15: MPE | B15: Department of Mechanical and Production Engineering | M15: Livestock/stable operations
A16: QGG | B16: Center for Quantitative Genetics and Genomics | M16: Other
M17: Audit
I18: De 6 tabeller hænger sammen og må ikke sorteres enkeltvis
A19: Job functions | B19: Column1 | D19: Currency | F19: Rate | I19: Funder | K19: Yearly hours | M19: OH rate | O19: Project-supplement | Q19: OH calculation basis | S19: Technical ass calculation basis
A20: PhD - High Rate | B20: PhD | D20: DKK | F20: 1 | I20: 15. Juni Fonden | K20: 1460 | M20: 0 | O20: None | Q20: Salary and operations | S20: Salary and operations
A21: PhD - Avr. Rate | B21: PhD | D21: EUR | F21: 7.45 | I21: ARLA | K21: 1460 | M21: 20 | O21: None | Q21: Salary and operations | S21: Salary and operations
A22: Research Assistent - avr. Rate | D22: SEK | F22: 0.67 | I22: AUFF - Aarhus Universitets Forskningsfond | K22: 1460 | M22: 20 | O22: None | Q22: Salary and operations | S22: Salary and operations
A23: Research Assistent - low rate | D23: NOK | F23: 0.68 | I23: Carlsbergfondet | K23: 1460 | M23: 0 | O23: Project-supplement | Q23: None | S23: None
A24: TAP/Other masters degree | B24: TAP/Other Masters degree | D24: USD | F24: 7.02 | I24: Danida | K24: 1460 | M24: 44 | O24: None | Q24: Salary and operations excl. External assistance/consultants | S24: Salary and operations
A25: Laboratory technician - high rate | B25: Laboratory technician | D25: Optional currency | F25: 0 | I25: DFF - Danmarks Frie Forskningsfond | K25: 1460 | M25: 44 | O25: None | Q25: Salary and operations | S25: Salary and operations
A26: Laboratory technician - avr. rate | B26: Laboratory technician | I26: EDF - European Defence Fund | K26: 1460 | M26: 0 | O26: None
A27: Laboratory technician - low rate | B27: Laboratory technician | I27: EIT - European Institute of Innovation & Technology | K27: 1485 | M27: 25 | O27: None | Q27: Salary and operations
A28: Technician - high rate | B28: Technician | D28: Type of budget | I28: EUDP - Energistyrelsen | K28: 1642 | M28: 44 | O28: None | Q28: Salary and operations | S28: Salary and operations
A29: Technician - avr. rate | B29: Technician | D29: External funding | I29: FRØ - Frøafgiftsfonden | K29: 1460 | M29: 44 | O29: None | Q29: Salary and operations excl. External assistance/consultants | S29: Operations
A30: Technician - low rate | B30: Technician | D30: Coverage | I30: GUDP - Landbrugsstyrelsen | K30: 1642 | M30: 44 | O30: None | Q30: Salary and operations | S30: Salary and operations
A31: Post Doc. - low rate | D31: Co-financing covered by department | I31: Plantefonden | K31: 1642 | M31: 44 | O31: None | Q31: Salary and operations | S31: Salary and operations
A32: Post Doc. - high rate | D32: Co-financing covered by other external funding | I32: H2020 | K32: 1485 | M32: 25 | O32: None | Q32: Salary and operations
A33: Senior advisor - high rate | I33: Horizon Europe | K33: 1485 | M33: 25 | O33: None | Q33: Salary and operations
A34: Senior advisor - avr. rate | I34: IFD - Innovationsfonden | K34: 1460 | M34: 44 | O34: None | Q34: Salary and operations | S34: Salary and operations
A35: Post Doc abroad (Applicant, no project supplement) - high rate | I35: Klimastøtte - Energistyrelsen | K35: 1642 | M35: 44 | O35: None | Q35: Salary and operations | S35: Salary and operations
A36: Post Doc abroad (Applicant, no project supplement) - low rate | D36: Overheadsrate | I36: LEO Foundation | K36: 1460 | M36: 0 | O36: Project-supplement | Q36: None | S36: None
D37: 0 | I37: Lundbeck Fonden | K37: 1460 | M37: 0 | O37: Project-supplement | Q37: None | S37: None
D38: 5 | I38: MAF - Mælkeafgiftsfonden | K38: 1460 | M38: 44 | O38: None | Q38: Salary and operations excl. External assistance/consultants | S38: Operations
A39: GDPR Related | D39: 10 | I39: Miljøstøtte - Miljøstyrelsen | K39: 1460 | M39: 44 | O39: None | Q39: Salary and operations | S39: Salary and operations
A40: Yes | D40: 15 | I40: MUDP - Miljøstyrelsen | K40: 1642 | M40: 44 | O40: None | Q40: Salary | S40: Salary and operations
A41: No | D41: 20 | I41: NIFA - LBST | K41: 1642 | M41: 44 | O41: None | Q41: Salary and operations | S41: Salary and operations
...

Sheet Guide
A1: Guide to "Internal Application Form"
A2: General
A3: Fill out your budget in B1-B5 | B3: Start by filling out your budget in the blue sheet 'B1'. If you need to enter more budgets - for example, because the project needs to be divided into WPs or there are multiple participants in the project, the next budgets can be entered in the blue sheets 'B2-B5'. If you need to budget beyond the 6 years, send the form to your FC/PC who will extend it by an additional 4 years. | C3: Start med at udfylde dit budget i det blå ark "B1". Har du brug for at indtaste flere budgetter - eks. fordi projektet skal deles op i WP eller I er flere deltagere i projektet kan de næste budgetter tastes de blå ark "B2-B5". Har du brug for at budgetlægge udover de 6 år så send skemaet til din FC/PC som vil udvide med ydereligere 4 år.
A4: Total budget | B4: You can see the total budget in the sheet "Total" which is a summation of "B1-B5" | C4: Du kan se det totale budget i arket "Total" som er en sammentælling af "B1-B5"
A5: Another valuta | B5: If you want your budget converted into another currency you can enter the currency in the sheet 'Total Other Currency' | C5: Hvis du ønsker dit budget omregnet i en anden valuta kan du taste valutaen i arket "Total Other Currency"
A6: PE | B6: The sheet 'PE' is used by the project controllers | C6: Arket "PE" anvendes af projektcontrollerne
A7: Add new grant source | B7: The sheet 'Add new grant source' is activated when you press the 'Add new' button in the Cover letters | C7: Arket "Add new grant source" aktiveres når man trykker på knappen "Add new" i Cover letteret.
A8: Cover Letter | B8: When you have completed your budget, you must fill out the current Cover Letter. It is up to the individual institute whether to use 'Cover Letter ECE' or 'Cover Letter | C8: Når du har udfyldt dit budget skal du udfylde det aktuelle Cover Letter. Det er op til det enkelte institut hvorvidt der benyttes "Cover Letter ECE" eller "Cover letter".
A9: Budget review | B9: Once you have completed the Cover Letter, send the application budget template to your business controller or project controller. They will check your budget according to the applicable guidelines for the grant provider and your department. Further approval of the budget and application must follow your department’s guidelines | C9: Når du er færdig med at udfylde Cover Letter sender du ansøgningsbudgetskabelonen til din forretningscontroller eller projektcontroller. De vil tjekke dit budget ifølge gældende retningslinjer for bevillingsgiver og dit institut. Ydereligere godkendelse af budget og ansøgning skal følge dit instituts retningslinjer
A10: Final application is sent to | B10: Once you have sent your application to the grant source you must send this along with the application budget template to the mailbox 'Nat-Tech Finance Application (nat-tech.finance.application@au.dk)' from where the application will be entered into ReAp and forwarded to your business controller/project controller | C10: Når du har sendt din ansøgning til bevillingsgiver skal du sende denne samt ansøgningsbudgetskabelonen til postkassen "Nat-Tech Finance Application (nat-tech.finance.application@au.dk)" hvorfra ansøgningen vil blive lagt i ReAp og videresendt til din forretningscontroller/projektcontroller
A11: Additional guidance | B11: For additional guidance, see the description of the individual fields below. You are also always welcome to ask the business controller or project controller | C11: For øvrig vejledning se beskrivelse af de enkelte felter nedenfor. Du er også altid velkommen til at spørge den forretningscontroller eller projektcontroller
A13: Description of the individual fields
A14: Field | B14: Description | C14: Beskrivelse
A15: Department | B15: A department must be selected from the list. It is possible to enter a department that is not on the list - in that case, the fields dependent on the department will be counted with value = 0 | C15: Der skal vælges et institut fra listen. Man kan godt skrive et institut, der ikke findes på listen - så vil de felter, der er afhængig af feltet blot regnes med værdi = 0.
A16: Projecttitle and acronym | B16: The project title must be filled in for the cover letter to be correctly completed | C16: Projekttitel skal udfyldes, så cover letter udfyldes korrekt.
A17: Grant holder | B17: The grant holder must be filled in for the cover letter to be correctly completed. | C17: Grant holder skal udfyldes, så cover letter udfyldes korrekt.
A18: Grant Source | B18: When a 'Grant Source' is selected from the list, information about the overhead rate and hourly standard is automatically filled in. If a 'Grant Source' not on the list is entered, you must fill in the fields correctly yourself. | C18: Når man vælger "Grant Source" fra listen, udfyldes oplysninger om overheadsats og timenorm. Hvis man skriver en "Grant Source", der ikke er på listen, skal man selv udfylde felterne korrekt. Oplysninger om overhead sats og timenorm kan findes i arket Lister.
A19: Insert overheads rate | B19: The field is automatically filled based on 'Grant Source'. You can overwrite the field with a different overhead rate or choose one from the list. However, note that if you overwrite or select another, the automatic correct filling function will be disabled. The calculation of overhead in the total budget depends on this field | C19: Feltet udfyldes automatisk pba "Grant Source". Man kan godt overskrive feltet med en anden overhead sats, eller man kan vælge en fra listen. Bemærk dog, at overskriver man eller vælger en anden, så forsvinder funktionen med at den automatisk udfyldes korrekt. Udregning af overhead i total budgettet er afhængigt af dette felt.
A20: Insert yearly count of hours | B20: The field is automatically filled based on 'Grant Source'. You can overwrite the field with a different number of hours or choose one from the list. However, note that if you overwrite or select another, the automatic correct filling function will be disabled. The field affects the calculation of Total hours | C20: Feltet udfyldes automatisk pba "Grant Source". Man kan godt overskrive feltet med et andet timetal, eller man kan vælge et fra listen. Bemærk dog, at overskriver man eller vælger et andet, så forsvinder funktionen med at den automatisk udfyldes korrekt. Feltet påvirker udregningen af Total hours
A21: Project supplement or Bench Fee | B21: The field is automatically filled with the project supplement based on 'Grant Source'. Novo Nordisk, Villum, Velux, Carlsberg, Lundbeck, and Leo provide project supplements. You can choose Bench fee from the list if the call indicates that a bench fee should be applied for instead of a project supplement. Note that if none of the foundations that provide project supplements or bench fees are selected, ensure that the field is filled with none | C21: Feltet udfyldes automatisk med projekttillæg pba "Grant Source". Det er Novo Nordisk, Villum, Velux, Carlsberg, Lundbeck og Leo der bevilliger projekttillæg. Man kan vælge Bench fee fra listen, hvis call'et angiver, at der skal søges om bench fee og ikke projekttillæg. Bemærk hvis der ikke er valgt en af de fonde, der giver projekttillæg eller bench fee, skal man sikre sig at feltet er udfyldt med none.
A22: Overhead calculation basis | B22: It is always pre-filled with Salary and operations. This has implications for which fields are used to calculate overhead. Currently, it is manually changed if it needs to be different. | C22: Er altid forudfyldt med Salary and operations. Har betydning for hvilke felter, der beregnes overhead af. Ændres p.t. manuelt hvis det skal være anderledes.
A23: Calculate tehcnical assis | B23: It is always pre-filled with Salary and operations. This affects whether supplements for technical assistance and lab rent, etc., are calculated. Currently, it is manually changed if it needs to be different | C23: Er altid forudfyldt med Salary and operations. Har betydning for om der beregnes tillæg til technical ass. and lab rent m.m. Ændres p.t. manuelt hvis det skal være anderledes.
A24: Is the project GDPR related | B24: The field is filled with yes or no. The information is used in the cover letter | C24: Feltet udfyldes med ja eller nej. Oplysningen bruges på cover letter.
A25: If Project Kind is Indtægtsdækket Virksomhed choose 2 | B25: If the project is a sub-account 2 project 'Commercial Activity', the field must be filled with the value 2, otherwise it should be left blank | C25: Hvis projektet er et delregnskab 2 projekt "Indtægtsdækket Virksomhed", skal feltet udfyldes med værdien 2, ellers skal den være blank.
... A41: Avg. hourly rate | B41: Total salary/total hours | C41: Total løn/total hours
A42: Total Cost
A43: - VIP-salary total | B43: The total sum of VIP salary | C43: Summen af VIP salary
A44: - TAP-salary total | B44: The total sum of TAP salary | C44: Summen af TAP salary
A45: - Operations total | B45: The total sum of operations | C45: Summen af operations
A46: - Overhead | B46: Overhead is calculated based on the choices made in 'Grant Source' + 'Insert overhead rate' + 'Overhead Calculation basis | C46: Overhead regnes pba de valg, der er foretaget i "Grant Source"+"Insert overhead rate"+"Overhead Calculation basis"
A47: - Bench fee | B47: Bench fee is calculated based on the choices made in 'Project supplement and Bench Fee'. A bench fee is calculated for all VIP months *8000 | C47: Bench fee regnes pba de valg, der er foretaget i "Project supplement and Bench Fee". Der beregnes bench fee af alle VIP-mdr. *8000
A48: - Project supplement | B48: Project supplement is calculated based on the choices made in 'Project supplement and Bench Fee'. Project supplements are given to Postdoc, PhD, and Research Assistant. Note: only from external funding and coverage. | C48: Project supplement regnes pba de valg, der er foretaget I "Project supplement and Bench Fee". Der gives projekt supplement til Postdoc, PhD og Research assistant. Bemærk kun af den eksterne finansiering og inddækning
A49: - EBIT | B49: EBIT is calculated based on the choices made in the 'EBIT' field | C49: EBIT regnes pba de valg, der er foretaget I feltet "EBIT"
A50: External funding (incl. coverage)
A51: - VIP-salary total | B51: The sum of VIP salary where 'external funding' or 'Coverage' is selected in the 'Type of budget | C51: Summen af VIP salary, hvor der I Type of budget er valgt external funding or Coverage
A52: - TAP-salary total | B52: The sum of TAP salary where 'external funding' or 'Coverage' is selected in the 'Type of budget | C52: Summen af TAP salary, hvor der I Type of budget er valgt external funding or Coverage
A53: - Operations total | B53: The sum of operations total where 'external funding' or 'Coverage' is selected in the 'Type of budget | C53: Summen af opreations total, hvor der I Type of budget er valgt external funding or Coverage
A54: - Overhead | B54: Overhead is calculated based on the choices made in 'Grant Source' + 'Insert overhead rate' + 'Overhead Calculation basis | C54: Overhead regnes pba de valg, der er foretaget i "Grant Source"+"Insert overhead rate"+"Overhead Calculation basis"
A55: - Bench fee | B55: Bench fee is calculated based on the choices made in 'Project supplement and Bench Fee'. A bench fee is calculated for all VIP months * 8000 | C55: Bench fee regnes pba de valg, der er foretaget i "Project supplement and Bench Fee". Der bergnes bench fee af alle VIP-mdr. *8000
A56: - Project supplement | B56: Project supplement is calculated based on the choices made in 'Project supplement and Bench Fee'. Project supplements are given to Postdoc, PhD, and Research Assistant. Note: only from external funding | C56: Project supplement regnes pba de valg, der er foretaget I "Project supplement and Bench Fee". Der gives projekt supplement til Postdoc, PhD og Research assistant. Bemærk kun af den eksterne finansiering
...

Sheet Cover letter ECE_MPE
B2: Cover letter for management for externally funded projects The green fields are to be filled in by the grant holder The grey fields retrieve information from the WPs that have the same department as in E5
B3: ReAp control | D3: =IFERROR(IF(AND(I5<>"", OR(C7<>"", LEN(TRIM(J7))>0), G5<>"", C9<>0, C12<>0, C13<>"", F12<>0, F13<>"", D20<>"", D22<>0, H35<>""), "✅ ReAp fields are completed", "❌ ReAp fields are missing data – Please fill in the yellow cells"), "❌ ReAp fields are missing data – Please fill in the yellow cells") -> ❌ ReAp fields are missing data – Please fill in the yellow cells
B5: Applicant name | C5: =+'B1'!C4 -> 0 | D5: Department | E5: =+'B1'!C2 -> 0 | F5: Section | H5: AUID | K5: =IF(OR('Cover letter'!I5>0,LEN(I5)<3),1,0) -> 1
B6: Projecttitle and acronym | C6: =+'B1'!C3 -> 0
B7: Grant source | J7: {=IF(IF(IF(C7="",Tabel21[Grant source])=0,"",IF(C7="",Tabel21[Grant source]))=FALSE,"",IF(IF(C7="",Tabel21[Grant source])=0,"",IF(C7="",Tabel21[Grant source])))} | K7: =IF(ISBLANK(C7),J7,_xlfn.XLOOKUP(C7,GrantSource!C:C,GrantSource!A:A))
B8: Instrument | J8: {=IF(IF(IF(C8="",Tabel21[Instrument])=0,"",IF(C8="",Tabel21[Instrument]))=FALSE,"",IF(IF(C8="",Tabel21[Instrument])=0,"",IF(C8="",Tabel21[Instrument])))} | K8: =IF(ISBLANK(C8),J8,C8)
B9: GDPR-related | C9: =+'B1'!H8 -> 0 | D9: Is there involvement from a country that poses a threat to Denmark according to URIS guidelines? | G9: Specify country:
B10: Participants from the dept.
B11: Is Applicant main coordinator of the project | D11: If no, please type the name of the coordinator
B12: Project start (dd.mm.yyyy) | C12: =+'B1'!C9 -> 0 | D12: Project end (dd.mm.yyyy) | F12: =+'B1'!H9 -> 0
B13: Deadline for application (dd-mm-yyyy) | D13: Next update expected (dd-mm-yyyy)
B14: Short project description
B15: Partners within AU(name and dept.)
B16: Partners outside AU
B17: Planned new recruitment of named scientific staff (CV enclosed)
B18: BUDGET
B19: Special remarks to budget
B20: Applied amount total incl. partners and overhead
B21: Total budget to the dept. (incl. co-financing) | D21: =+IF('B1'!C2='Cover letter ECE_MPE'!E5,'B1'!AC73,0)+IF('B2'!C2='Cover letter ECE_MPE'!E5,'B2'!AC73,0)+IF('B3'!C2='Cover letter ECE_MPE'!E5,'B3'!AC73,0)+IF('B4'!C2='Cover letter ECE_MPE'!E5,'B4'!AC73,0)+IF('B5'!C2='Cover letter ECE_MPE'!E5,'B5'!AC73,0) -> 0
B22: Applied amount to the dept. incl. overhead | D22: =+IF(E5='B1'!C2,'B1'!AC89,0)+IF(E5='B2'!C2,'B2'!AC89,0)+IF(E5='B3'!C2,'B3'!AC89,0)+IF(E5='B4'!C2,'B4'!AC89,0)+IF(E5='B5'!C2,'B5'!AC89,0) -> 0
B23: Overhead/project supplement/BenchFee/EBIT | D23: =+IF(E5='B1'!C2,SUM('B1'!AC85:AC88),0)+IF(E5='B2'!C2,SUM('B2'!AC85:AC88),0)+IF(E5='B3'!C2,SUM('B3'!AC85:AC88),0)+IF(E5='B4'!C2,SUM('B4'!AC85:AC88),0)+IF(E5='B5'!C2,SUM('B5'!AC85:AC88),0) -> 0
B24: Cost Coverage salary | D24: =+IF('B1'!C2='Cover letter ECE_MPE'!E5,SUMIF('B1'!O20:O55,Lister!D30,'B1'!AC20:AC56),0)+IF('B2'!C2='Cover letter ECE_MPE'!E5,SUMIF('B2'!O20:O55,Lister!D30,'B2'!AC20:AC56),0)+IF('B3'!C2='Cover letter ECE_MPE'!E5,SUMIF('B3'!O20:O55,Lister!D30,'B3'!AC20:AC56),0)+IF('B4'!C2='Cover letter ECE_MPE'!E5,SUMIF('B4'!O20:O55,Lister!D30,'B4'!AC20:AC56),0)+IF('B5'!C2='Cover letter ECE_MPE'!E5,SUMIF('B5'!O20:O55,Lister!D30,'B5'!AC20:AC56),0) -> 0
B25: Cost Coverage others | D25: =(IF('B1'!C2='Cover letter ECE_MPE'!E5,SUMIF('B1'!O62:O74,Lister!D30,'B1'!M62:M74),0)+IF('B2'!C2='Cover letter ECE_MPE'!E5,SUMIF('B2'!O62:O74,Lister!D30,'B2'!M62:M74),0)+IF('B3'!C2='Cover letter ECE_MPE'!E5,SUMIF('B3'!O62:O74,Lister!D30,'B3'!M62:M74),0)+IF('B4'!C2='Cover letter ECE_MPE'!E5,SUMIF('B4'!O62:O74,Lister!D30,'B4'!M62:M74),0)+IF('B5'!C2='Cover letter ECE_MPE'!E5,SUMIF('B5'!O62:O74,Lister!D30,'B5'!M62:M74),0)) -> 0
B26: Department co-financing salary | D26: =+IF('B1'!C2='Cover letter ECE_MPE'!E5,SUMIF('B1'!O20:O55,Lister!D31,'B1'!AC20:AC56),0)+IF('B2'!C2='Cover letter ECE_MPE'!E5,SUMIF('B2'!O20:O55,Lister!D31,'B2'!AC20:AC56),0)+IF('B3'!C2='Cover letter ECE_MPE'!E5,SUMIF('B3'!O20:O55,Lister!D31,'B3'!AC20:AC56),0)+IF('B4'!C2='Cover letter ECE_MPE'!E5,SUMIF('B4'!O20:O55,Lister!D31,'B4'!AC20:AC56),0)+IF('B5'!C2='Cover letter ECE_MPE'!E5,SUMIF('B5'!O20:O55,Lister!D31,'B5'!AC20:AC56),0) -> 0 | F26: Department co-financing | G26: =+(D26+D27)/D21 -> #DIV/0!
